ERROR:root:Aldi: garlic was not interactable
ERROR:root:Aldi: check value for aubergine; 3 validation errors for Ingredient
WARNING:urllib3.connectionpool:Retrying (Retry(total=2, connect=None, read=None, redirect=None, status=None)) after connection broken by 'NewConnectionError('<urllib3.connection.HTTPConnection object at 0x152f00a90>: Failed to establish a new connection: [Errno 61] Connection refused')': /session/68af8ca9ed4cc52913cb861d9ec40126
WARNING:urllib3.connectionpool:Retrying (Retry(total=1, connect=None, read=None, redirect=None, status=None)) after connection broken by 'NewConnectionError('<urllib3.connection.HTTPConnection object at 0x152f00e80>: Failed to establish a new connection: [Errno 61] Connection refused')': /session/68af8ca9ed4cc52913cb861d9ec40126
WARNING:urllib3.connectionpool:Retrying (Retry(total=0, connect=None, read=None, redirect=None, status=None)) after connection broken by 'NewConnectionError('<urllib3.connection.HTTPConnection object at 0x152eec670>: Failed to establish a new connection: [Errno 61] Connection refused')': /session/68af8ca9ed4cc52913cb861d9ec40126
ERROR:root:Aldi: check value for aubergine; 2 validation errors for Ingredient
shop
  Field required [type=missing, input_value={'name': 'aubergine', 'pr...: 0.89, 'unit': 'whole'}, input_type=dict]
    For further information visit https://errors.pydantic.dev/2.5/v/missing
last_update
  Field required [type=missing, input_value={'name': 'aubergine', 'pr...: 0.89, 'unit': 'whole'}, input_type=dict]
    For further information visit https://errors.pydantic.dev/2.5/v/missing
ERROR:root:Aldi: check value for aubergine; 2 validation errors for Ingredient
shop
  Field required [type=missing, input_value={'name': 'aubergine', 'pr...: 0.89, 'unit': 'whole'}, input_type=dict]
    For further information visit https://errors.pydantic.dev/2.5/v/missing
last_update
  Field required [type=missing, input_value={'name': 'aubergine', 'pr...: 0.89, 'unit': 'whole'}, input_type=dict]
    For further information visit https://errors.pydantic.dev/2.5/v/missing
ERROR:root:Aldi: check value for aubergine; 2 validation errors for Ingredient
shop
  Field required [type=missing, input_value={'name': 'aubergine', 'pr...: 0.89, 'unit': 'whole'}, input_type=dict]
    For further information visit https://errors.pydantic.dev/2.5/v/missing
last_update
  Field required [type=missing, input_value={'name': 'aubergine', 'pr...: 0.89, 'unit': 'whole'}, input_type=dict]
    For further information visit https://errors.pydantic.dev/2.5/v/missing
WARNING:urllib3.connectionpool:Retrying (Retry(total=2, connect=None, read=None, redirect=None, status=None)) after connection broken by 'ConnectionResetError(54, 'Connection reset by peer')': /session/d4bbbcf694e5331cffc4986a1250efff
WARNING:urllib3.connectionpool:Retrying (Retry(total=1, connect=None, read=None, redirect=None, status=None)) after connection broken by 'NewConnectionError('<urllib3.connection.HTTPConnection object at 0x118b24490>: Failed to establish a new connection: [Errno 61] Connection refused')': /session/d4bbbcf694e5331cffc4986a1250efff
WARNING:urllib3.connectionpool:Retrying (Retry(total=0, connect=None, read=None, redirect=None, status=None)) after connection broken by 'NewConnectionError('<urllib3.connection.HTTPConnection object at 0x118b24100>: Failed to establish a new connection: [Errno 61] Connection refused')': /session/d4bbbcf694e5331cffc4986a1250efff
